[2025-03-15 09:19:07 +0000] [34401] [INFO] Starting gunicorn 23.0.0
[2025-03-15 09:19:07 +0000] [34401] [INFO] Listening at: http://0.0.0.0:5000 (34401)
[2025-03-15 09:19:07 +0000] [34401] [INFO] Using worker: sync
[2025-03-15 09:19:07 +0000] [34402] [INFO] Booting worker with pid: 34402
[2025-03-15 09:19:07 +0000] [34403] [INFO] Booting worker with pid: 34403
[2025-03-15 09:19:07 +0000] [34405] [INFO] Booting worker with pid: 34405
[2025-03-15 09:19:07 +0000] [34406] [INFO] Booting worker with pid: 34406
[2025-03-15 09:19:26,047] ERROR in app: Exception on / [GET]
Traceback (most recent call last):
  File "/home/ec2-user/.local/lib/python3.9/site-packages/flask/app.py", line 1511, in wsgi_app
    response = self.full_dispatch_request()
  File "/home/ec2-user/.local/lib/python3.9/site-packages/flask/app.py", line 919, in full_dispatch_request
    rv = self.handle_user_exception(e)
  File "/home/ec2-user/.local/lib/python3.9/site-packages/flask/app.py", line 917, in full_dispatch_request
    rv = self.dispatch_request()
  File "/home/ec2-user/.local/lib/python3.9/site-packages/flask/app.py", line 902, in dispatch_request
    return self.ensure_sync(self.view_functions[rule.endpoint])(**view_args)  # type: ignore[no-any-return]
  File "/home/ec2-user/Cep-AI/app.py", line 59, in index
    return render_template('index.html', predicted_cgpa=None, error=None)
  File "/home/ec2-user/.local/lib/python3.9/site-packages/flask/templating.py", line 149, in render_template
    template = app.jinja_env.get_or_select_template(template_name_or_list)
  File "/home/ec2-user/.local/lib/python3.9/site-packages/jinja2/environment.py", line 1087, in get_or_select_template
    return self.get_template(template_name_or_list, parent, globals)
  File "/home/ec2-user/.local/lib/python3.9/site-packages/jinja2/environment.py", line 1016, in get_template
    return self._load_template(name, globals)
  File "/home/ec2-user/.local/lib/python3.9/site-packages/jinja2/environment.py", line 975, in _load_template
    template = self.loader.load(self, name, self.make_globals(globals))
  File "/home/ec2-user/.local/lib/python3.9/site-packages/jinja2/loaders.py", line 126, in load
    source, filename, uptodate = self.get_source(environment, name)
  File "/home/ec2-user/.local/lib/python3.9/site-packages/flask/templating.py", line 65, in get_source
    return self._get_source_fast(environment, template)
  File "/home/ec2-user/.local/lib/python3.9/site-packages/flask/templating.py", line 99, in _get_source_fast
    raise TemplateNotFound(template)
jinja2.exceptions.TemplateNotFound: index.html
[2025-03-15 09:19:30,823] ERROR in app: Exception on / [GET]
Traceback (most recent call last):
  File "/home/ec2-user/.local/lib/python3.9/site-packages/flask/app.py", line 1511, in wsgi_app
    response = self.full_dispatch_request()
  File "/home/ec2-user/.local/lib/python3.9/site-packages/flask/app.py", line 919, in full_dispatch_request
    rv = self.handle_user_exception(e)
  File "/home/ec2-user/.local/lib/python3.9/site-packages/flask/app.py", line 917, in full_dispatch_request
    rv = self.dispatch_request()
  File "/home/ec2-user/.local/lib/python3.9/site-packages/flask/app.py", line 902, in dispatch_request
    return self.ensure_sync(self.view_functions[rule.endpoint])(**view_args)  # type: ignore[no-any-return]
  File "/home/ec2-user/Cep-AI/app.py", line 59, in index
    return render_template('index.html', predicted_cgpa=None, error=None)
  File "/home/ec2-user/.local/lib/python3.9/site-packages/flask/templating.py", line 149, in render_template
    template = app.jinja_env.get_or_select_template(template_name_or_list)
  File "/home/ec2-user/.local/lib/python3.9/site-packages/jinja2/environment.py", line 1087, in get_or_select_template
    return self.get_template(template_name_or_list, parent, globals)
  File "/home/ec2-user/.local/lib/python3.9/site-packages/jinja2/environment.py", line 1016, in get_template
    return self._load_template(name, globals)
  File "/home/ec2-user/.local/lib/python3.9/site-packages/jinja2/environment.py", line 975, in _load_template
    template = self.loader.load(self, name, self.make_globals(globals))
  File "/home/ec2-user/.local/lib/python3.9/site-packages/jinja2/loaders.py", line 126, in load
    source, filename, uptodate = self.get_source(environment, name)
  File "/home/ec2-user/.local/lib/python3.9/site-packages/flask/templating.py", line 65, in get_source
    return self._get_source_fast(environment, template)
  File "/home/ec2-user/.local/lib/python3.9/site-packages/flask/templating.py", line 99, in _get_source_fast
    raise TemplateNotFound(template)
jinja2.exceptions.TemplateNotFound: index.html
 * Serving Flask app 'app'
 * Debug mode: on
WARNING: This is a development server. Do not use it in a production deployment. Use a production WSGI server instead.
 * Running on all addresses (0.0.0.0)
 * Running on http://127.0.0.1:5000
 * Running on http://172.31.29.202:5000
Press CTRL+C to quit
 * Restarting with stat
 * Debugger is active!
 * Debugger PIN: 495-194-666
139.135.55.218 - - [16/Mar/2025 00:40:21] "GET / HTTP/1.1" 200 -
139.135.55.218 - - [16/Mar/2025 00:40:22] "GET /static/logo.png HTTP/1.1" 304 -
139.135.55.218 - - [16/Mar/2025 00:40:23] "GET /favicon.ico HTTP/1.1" 404 -
139.135.55.218 - - [16/Mar/2025 00:42:01] "GET / HTTP/1.1" 200 -
139.135.55.218 - - [16/Mar/2025 00:42:01] "GET /static/logo.png HTTP/1.1" 200 -
139.135.55.218 - - [16/Mar/2025 00:42:02] "GET /favicon.ico HTTP/1.1" 404 -
139.135.55.218 - - [16/Mar/2025 00:42:48] "GET / HTTP/1.1" 200 -
139.135.55.218 - - [16/Mar/2025 00:42:49] "GET /static/logo.png HTTP/1.1" 304 -
